Workbook
Name b_1: [2]가정단면!$Q$28

Sheet 검토결과 요약(인쇄X)
K5: 상시 | L5: 지진시 | M5: 합계 | N5: 허용 | O5: 평가결과
A6: 1 | B6: =#REF! -> #REF! | C6: =#REF! -> #REF! | D6: =#REF! -> #REF! | E6: =#REF! -> #REF! | F6: =#REF! -> #REF! | G6: =#REF! -> #REF! | H6: =#REF! -> #REF! | I6: =#REF! -> #REF! | ... N6: =#REF! -> #REF! | O6: =IF(N6/M6<1,"NG","OK") -> #REF!
A7: 2 | B7: =#REF! -> #REF! | C7: =#REF! -> #REF! | D7: =#REF! -> #REF! | E7: =#REF! -> #REF! | F7: =#REF! -> #REF! | G7: =#REF! -> #REF! | H7: =#REF! -> #REF! | I7: =#REF! -> #REF! | ... N7: =#REF! -> #REF! | O7: =IF(N7/M7<1,"NG","OK") -> #REF!
A8: 3 | B8: =#REF! -> #REF! | C8: =#REF! -> #REF! | D8: =#REF! -> #REF! | E8: =#REF! -> #REF! | F8: =#REF! -> #REF! | G8: =#REF! -> #REF! | H8: =#REF! -> #REF! | I8: =#REF! -> #REF! | ... N8: =#REF! -> #REF! | O8: =IF(N8/M8<1,"NG","OK") -> #REF!
A9: 17 | B9: ='하안송수관로 01(01)'!$AA$1 -> 0 | C9: ='하안송수관로 01(01)'!$AB$1 -> 0 | D9: ='하안송수관로 01(01)'!$N$314 -> 3 | E9: ='하안송수관로 01(01)'!$N$317 -> 0.154 | F9: ='하안송수관로 01(01)'!$N$318 -> 0.245 | G9: =#REF! -> #REF! | H9: =#REF! -> #REF! | I9: =#REF! -> #REF! | J9: =#REF! -> #REF! | K9: ='하안송수관로 01(01)'!$AF$327 -> 0.039349429 | L9: ='하안송수관로 01(01)'!$AG$327 -> 0.017609984 | M9: ='하안송수관로 01(01)'!$AH$327 -> 0.056959413 | N9: ='하안송수관로 01(01)'!$AI$327 -> 0.368 | O9: =IF(N9/M9<1,"NG","OK") -> OK

Sheet 하안송수관로 01(01)
A1: ■ 하안 송수관로 01(01) Sta. No. 4+15.0 강관 내진안전성평가
A3: 1) 관체 제원 및 설계조건
B4: - 설계내압(P) | J4: = | K4: 1.733 | O4: MPa | Q4: = | R4: =K4*1000 -> 1733 | W4: kN/m2
B5: - 매설깊이(h) | J5: = | K5: 4 | O5: m | P5: >>> | R5: 관중심 심도(z) = | V5: =ROUND(K5+R14/2,3) -> 4.5 | Z5: m
B6: - 흙의 단위중량(γ) | J6: = | K6: 19 | O6: kN/m2
B7: - 온도변화(T) | J7: = | K7: 20 | O7: ℃
B8: - 기반암 심도(H) | J8: = | K8: =K74 -> 12 | O8: m
B9: - 차량하중(Pm) | J9: = | K9: 없음 | P9: >>> | R9: =IF(K9="없음",0,IF(K9="DB-24",96,IF(K9="DB-18",72,54))) -> 0 | V9: kN/輪
B10: - 연약지반구간(Lδ) | J10: = | K10: 0 | O10: m | P10: , | Q10: 성토높이(h") | T10: = | U10: 0 | Y10: m
B12: E | C12: (관의 탄성계수) | J12: = | K12: 210000 | O12: MPa | Q12: = | R12: =K12*1000 -> 210000000 | W12: kN/m2
B13: t | C13: (관두께) | J13: = | K13: 8 | O13: mm | Q13: = | R13: =K13/1000 -> 0.008 | V13: m
B14: D | C14: (관외경) | J14: = | K14: 1000 | O14: mm | Q14: = | R14: =K14/1000 -> 1 | V14: m
B15: len | C15: (관길이) | J15: = | K15: 6000 | O15: mm | Q15: = | R15: =K15/1000 -> 6 | V15: m
B16: A | C16: (강관의 단면적) | J16: = | K16: =PI()*(K14-K13)*K13 -> 24931.679 | O16: mm2 | Q16: = | R16: =K16*10^-6 -> 0.024931679 | V16: m2
B17: I | C17: (강관의 단면2차모멘트) | J17: = | K17: =((PI()*(K14)^4)/64)-((PI()*(K14-K13*2)^4)/64) -> 3.0669955e+09 | O17: mm4 | Q17: = | R17: =K17*10^-12 -> 0.0030669955 | V17: m4
B19: - 지반정보 | E19: (수도권 광역상수도 안정화사업 실시설계)
B20: ∙ 매설관로에 인접한 위치의 지반조사 자료(시추조사, 표준관입시험, 다운홀 테스트 등)를 활용함
B21: ∙ 토층별 전단파 속도 데이터가 없을 경우, 표준관입시험 관입저항치(SPT-N치)를 전단파 속도로 변환하며, | AB21: <<< | AC21: 연암층, 경암층 보통암층은 기반암으로 적용
B22: 변환에는 국내 지반에 대해 제안된 상관관계식(Sun et al. 2013) Vs=65.64 × N0.407(m/sec)을 활용하여 산정함 | AB22: <<< | AC22: 토피고 제외 벽체 옆 층은 최대까지 2개까지 분류
B24: 토 층 | F24: 층두께(m) | I24: N치 | L24: 환산N치 | O24: 초기전단파 속도 (Vsi, m/s) | S24: di/Vsi | V24: 비 고 | AC24: 직접입력
B25: 매립층 | F25: 6.5 | I25: 3 | J25: / | K25: 30 | L25: =IFERROR(IF(K25=30,I25,IF((50*30/K25)>=300,"300",50*30/K25)),"") -> 3 | O25: =IF(OR(AC25="",AC25=0),IFERROR(ROUND(65.64*L25^0.407,2),IF(OR(B25="연암층",B25="경암층",B25="보통암층",B25="기반암층"),760,"")),AC25) -> 102.65 | S25: =IFERROR(F25/O25,"-") -> 0.063321968 | AA25: =F25 -> 6.5
B26: 퇴적층 | F26: 1.1 | I26: 47 | J26: / | K26: 30 | L26: =IFERROR(IF(K26=30,I26,IF((50*30/K26)>=300,"300",50*30/K26)),"") -> 47 | O26: =IF(OR(AC26="",AC26=0),IFERROR(ROUND(65.64*L26^0.407,2),IF(OR(B26="연암층",B26="경암층",B26="보통암층",B26="기반암층"),760,"")),AC26) -> 314.57 | S26: =IFERROR(F26/O26,"-") -> 0.003496837 | AA26: =F26+AA25 -> 7.6
B27: 풍화토층 | F27: 4.4 | I27: 47 | J27: / | K27: 30 | L27: =IFERROR(IF(K27=30,I27,IF((50*30/K27)>=300,"300",50*30/K27)),"") -> 47 | O27: =IF(OR(AC27="",AC27=0),IFERROR(ROUND(65.64*L27^0.407,2),IF(OR(B27="연암층",B27="경암층",B27="보통암층",B27="기반암층"),760,"")),AC27) -> 314.57 | S27: =IFERROR(F27/O27,"-") -> 0.013987348 | AA27: =F27+AA26 -> 12
L28: =IFERROR(IF(K28=30,I28,IF((50*30/K28)>=300,"300",50*30/K28)),"") | O28: =IF(OR(AC28="",AC28=0),IFERROR(ROUND(65.64*L28^0.407,2),IF(OR(B28="연암층",B28="경암층",B28="보통암층",B28="기반암층"),760,"")),AC28) | S28: =IFERROR(F28/O28,"-") -> - | AA28: =F28+AA27 -> 12
L29: =IFERROR(IF(K29=30,I29,IF((50*30/K29)>=300,"300",50*30/K29)),"") | O29: =IF(OR(AC29="",AC29=0),IFERROR(ROUND(65.64*L29^0.407,2),IF(OR(B29="연암층",B29="경암층",B29="보통암층",B29="기반암층"),760,"")),AC29) | S29: =IFERROR(F29/O29,"-") -> - | AA29: =F29+AA28 -> 12
L30: =IFERROR(IF(K30=30,I30,IF((50*30/K30)>=300,"300",50*30/K30)),"") | O30: =IF(OR(AC30="",AC30=0),IFERROR(ROUND(65.64*L30^0.407,2),IF(OR(B30="연암층",B30="경암층",B30="보통암층",B30="기반암층"),760,"")),AC30) | S30: =IFERROR(F30/O30,"-") -> - | AA30: =F30+AA29 -> 12
J31: / | L31: =IFERROR(IF(K31=30,I31,IF((50*30/K31)>=300,"300",50*30/K31)),"") | O31: =IF(OR(AC31="",AC31=0),IFERROR(ROUND(65.64*L31^0.407,2),IF(OR(B31="연암층",B31="경암층",B31="보통암층",B31="기반암층"),760,"")),AC31) | S31: =IFERROR(F31/O31,"-") -> - | AA31: =F31+AA30 -> 12
J32: / | L32: =IFERROR(IF(K32=30,I32,IF((50*30/K32)>=300,"300",50*30/K32)),"") | O32: =IF(OR(AC32="",AC32=0),IFERROR(ROUND(65.64*L32^0.407,2),IF(OR(B32="연암층",B32="경암층",B32="보통암층",B32="기반암층"),760,"")),AC32) | S32: =IFERROR(F32/O32,"-") -> - | AA32: =F32+AA31 -> 12
J33: / | L33: =IFERROR(IF(K33=30,I33,IF((50*30/K33)>=300,"300",50*30/K33)),"") | O33: =IF(OR(AC33="",AC33=0),IFERROR(ROUND(65.64*L33^0.407,2),IF(OR(B33="연암층",B33="경암층",B33="보통암층",B33="기반암층"),760,"")),AC33) | S33: =IFERROR(F33/O33,"-") -> - | AA33: =F33+AA32 -> 12
J34: / | L34: =IFERROR(IF(K34=30,I34,IF((50*30/K34)>=300,"300",50*30/K34)),"") | O34: =IF(OR(AC34="",AC34=0),IFERROR(ROUND(65.64*L34^0.407,2),IF(OR(B34="연암층",B34="경암층",B34="보통암층",B34="기반암층"),760,"")),AC34) | S34: =IFERROR(F34/O34,"-") -> -
J35: / | L35: =IFERROR(IF(K35=30,I35,IF((50*30/K35)>=300,"300",50*30/K35)),"") | O35: =IF(OR(AC35="",AC35=0),IFERROR(ROUND(65.64*L35^0.407,2),IF(OR(B35="연암층",B35="경암층",B35="보통암층",B35="기반암층"),760,"")),AC35) | S35: =IFERROR(F35/O35,"-") -> -
J36: / | L36: =IFERROR(IF(K36=30,I36,IF((50*30/K36)>=300,"300",50*30/K36)),"") | O36: =IF(OR(AC36="",AC36=0),IFERROR(ROUND(65.64*L36^0.407,2),IF(OR(B36="연암층",B36="경암층",B36="보통암층",B36="기반암층"),760,"")),AC36) | S36: =IFERROR(F36/O36,"-") -> -
J37: / | L37: =IFERROR(IF(K37=30,I37,IF((50*30/K37)>=300,"300",50*30/K37)),"") | O37: =IF(OR(AC37="",AC37=0),IFERROR(ROUND(65.64*L37^0.407,2),IF(OR(B37="연암층",B37="경암층",B37="보통암층",B37="기반암층"),760,"")),AC37) | S37: =IFERROR(F37/O37,"-") -> -
J38: / | L38: =IFERROR(IF(K38=30,I38,IF((50*30/K38)>=300,"300",50*30/K38)),"") | O38: =IF(OR(AC38="",AC38=0),IFERROR(ROUND(65.64*L38^0.407,2),IF(OR(B38="연암층",B38="경암층",B38="보통암층",B38="기반암층"),760,"")),AC38) | S38: =IFERROR(F38/O38,"-") -> -
J39: / | L39: =IFERROR(IF(K39=30,I39,IF((50*30/K39)>=300,"300",50*30/K39)),"") | O39: =IF(OR(AC39="",AC39=0),IFERROR(ROUND(65.64*L39^0.407,2),IF(OR(B39="연암층",B39="경암층",B39="보통암층",B39="기반암층"),760,"")),AC39) | S39: =IFERROR(F39/O39,"-") -> -
J40: / | L40: =IFERROR(IF(K40=30,I40,IF((50*30/K40)>=300,"300",50*30/K40)),"") | O40: =IF(OR(AC40="",AC40=0),IFERROR(ROUND(65.64*L40^0.407,2),IF(OR(B40="연암층",B40="경암층",B40="보통암층",B40="기반암층"),760,"")),AC40) | S40: =IFERROR(F40/O40,"-") -> -
B41: ※ 표준관입시험 시 단단한 암질에 도달하여 항타수가 50에 이르러도 30cm 깊이를 관입하지 못할 경우
B42: 50타수 이상의 N값은 선형적인 비례관계를 토대로 30cm 두께 관입 시 N값으로 환산함
B43: (이때 환산 N치의 최대값은 300으로 함)
B44: ※ 통상 N치 50이상의 암반층(연암 이상)은 N값 측정이 어려움으로, 암반층의 물성치가 명확하지
...

Sheet 주철관 Sta.No 0+0.0
A1: ■ Sta.No.0 + 0.0 주철관 내진안전성평가
A3: 1) 관체 제원 및 설계조건
C4: - 설계내압(P) | J4: = | K4: 1 | O4: MPa | Q4: = | R4: =K4*1000 -> 1000 | W4: kN/m2
C5: - 매설깊이(h) | J5: = | K5: 1.5 | O5: m | P5: >>> | R5: 관중심 심도(z) = | V5: =ROUND(K5+R14/2,3) -> 1.95 | Z5: m
C6: - 흙의 단위중량(γ) | J6: = | K6: 17 | O6: kN/m2
C7: - 온도변화(T) | J7: = | K7: 20 | O7: ℃
C8: - 기반암 심도(H) | J8: = | K8: =K64 -> 15 | O8: m
C9: - 차량하중(Pm) | J9: = | K9: DB-13.5 | P9: >>> | R9: =IF(K9="없음",0,IF(K9="DB-24",96,IF(K9="DB-18",72,54))) -> 54 | V9: kN/輪
C10: - 부등침하(δ) | J10: = | K10: 0.2 | O10: m | P10: , | Q10: 영향길이(Lδ) | T10: = | U10: 30 | Y10: m
B12: E | C12: (관의 탄성계수) | J12: = | K12: 160000 | O12: MPa | Q12: = | R12: =K12*1000 -> 160000000 | W12: kN/m2
B13: t | C13: (관두께) | J13: = | K13: 13 | O13: mm | Q13: = | R13: =K13/1000 -> 0.013 | V13: m
B14: D | C14: (관외경) | J14: = | K14: 900 | O14: mm | Q14: = | R14: =K14/1000 -> 0.9 | V14: m
B15: len | C15: (관길이) | J15: = | K15: 6000 | O15: mm | Q15: = | R15: =K15/1000 -> 6 | V15: m
B16: A | C16: (강관의 단면적) | J16: = | K16: =PI()*(K14-AC17)*AC17 -> 32976.337 | O16: mm2 | Q16: = | R16: =K16*10^-6 -> 0.032976337 | V16: m2 | AB16: 공칭관두께로부터 주철구조물 공차를 뺀 관두께
B17: I | C17: (강관의 단면2차모멘트) | J17: = | K17: =((PI()*(K14)^4)/64)-((PI()*(K14-AC17*2)^4)/64) -> 3.2523185e+09 | O17: mm4 | Q17: = | R17: =K17*10^-12 -> 0.0032523185 | V17: m4 | AB17: >>> t | AC17: =K13/1.1 -> 11.818182 | AD17: mm
A19: 2) 설계지진력 산정
B20: ( 1 ) 소요내진성능수준 : | H20: 기능수행수준, 붕괴방지수준
B22: ( 2 ) 지진구역 및 구역계수(Z)
B23: 지진구역 | E23: 행 정 구 역 | T23: 구역계수
B24: I | E24: 시 | G24: 서울특별시, 인천광역시, 대전광역시, 부산광역시, 대구광역시 울산광역시, 광주광역시, 세종특별자치시 | T24: 0.11
E26: 도 | G26: 경기도, 강원도 남부 , 충청북도, 충청남도, 경상북도, 경상남도, 전라북도, 전라남도
B28: II | E28: 도 | G28: 강원도 북부, 제주특별자치도 | T28: 0.07
B31: ( 3 ) 상수도 시설물의 내진등급과 설계지진
B32: 내진등급 | G32: 구 분 | T32: 재현주기
T33: 기능수행 | W33: 붕괴방지
B34: 내진1등급 | G34: 대체시설이 없는 송․배수 간선시설, 중요시설과 연결된 급수공급관로, 복구 난이도가 높은 환경에 놓이는 시설, 지진재해시 긴급대처 거점시설, 중대한 2 차 재해를 유발시킬 가능성이 있는 시설 등 | T34: 100년 | W34: 1,000년
B38: 내진2등급 | G38: 내진Ⅰ등급 이외의 시설 | T38: 50년 | W38: 500년
B41: ( 4 ) 위험도계수(I)
B42: 재현주기 | E42: 50년 | H42: 100년 | K42: 200년 | N42: 500년 | Q42: 1,000년 | T42: 2,400년 | W42: 4,800년
B43: 위험도 계수 | E43: 0.4 | H43: 0.57 | K43: 0.73 | N43: 1 | Q43: 1.4 | T43: 2 | W43: 2.6
B45: ( 5 ) 지반분류
B46: ① N값에 의한 전단파속도 결정
B47: ∙ 매설관로에 인접한 위치의 지반조사 자료(시추조사, 표준관입시험, 다운홀 테스트 등)를 활용함
B48: ∙ 토층별 전단파 속도 데이터가 없을 경우, 표준관입시험 관입저항치(SPT-N치)를 전단파 속도로 변환하며, | AB48: <<< | AC48: 연암층, 경암층 보통암층은 기반암으로 적용
B49: 변환에는 국내 지반에 대해 제안된 상관관계식(Sun et al. 2013) Vs=65.64 × N0.407(m/sec)을 활용하여 산정함 | AB49: <<< | AC49: 토피고 제외 벽체 옆 층은 최대까지 2개까지 분류
B51: 토 층 | F51: 층두께(m) | I51: N치 | L51: 환산N치 | O51: 초기전단파 속도 (VSi, m/s) | S51: C | U51: 설계전단파 속도 (VDSi, m/s) | AC51: 직접입력
B52: 매립층 | F52: 10 | I52: 5 | J52: / | K52: 25 | L52: =IFERROR(IF(K52=30,I52,IF((50*30/K52)>=300,"300",50*30/K52)),"") -> 60 | O52: =IF(OR(AC52="",AC52=0),IFERROR(ROUND(65.64*L52^0.407,2),IF(OR(B52="연암층",B52="경암층",B52="보통암층",B52="기반암층"),760,"")),AC52) -> 347.44 | S52: =IF(O52="","",IF(O52>360,1,0.8)) -> 0.8 | U52: =IF(ISERROR(O52*S52),"",O52*S52) -> 277.952
B53: 매립층-2 | F53: 5 | I53: 20 | J53: / | K53: 30 | L53: =IFERROR(IF(K53=30,I53,IF((50*30/K53)>=300,"300",50*30/K53)),"") -> 20 | O53: =IF(OR(AC53="",AC53=0),IFERROR(ROUND(65.64*L53^0.407,2),IF(OR(B53="연암층",B53="경암층",B53="보통암층",B53="기반암층"),760,"")),AC53) -> 222.17 | S53: =IF(O53="","",IF(O53>360,1,0.8)) -> 0.8 | U53: =IF(ISERROR(O53*S53),"",O53*S53) -> 177.736
J54: / | L54: =IFERROR(IF(K54=30,I54,IF((50*30/K54)>=300,"300",50*30/K54)),"") | O54: =IF(OR(AC54="",AC54=0),IFERROR(ROUND(65.64*L54^0.407,2),IF(OR(B54="연암층",B54="경암층",B54="보통암층",B54="기반암층"),760,"")),AC54) | S54: =IF(O54="","",IF(O54>360,1,0.8)) | U54: =IF(ISERROR(O54*S54),"",O54*S54)
J55: / | L55: =IFERROR(IF(K55=30,I55,IF((50*30/K55)>=300,"300",50*30/K55)),"") | O55: =IF(OR(AC55="",AC55=0),IFERROR(ROUND(65.64*L55^0.407,2),IF(OR(B55="연암층",B55="경암층",B55="보통암층",B55="기반암층"),760,"")),AC55) | S55: =IF(O55="","",IF(O55>360,1,0.8)) | U55: =IF(ISERROR(O55*S55),"",O55*S55)
...

Sheet 설계응답스펙트럼(출력 X)
B1: ◆ 기능수행수준 | F1: ◆ 붕괴방지수준
B2: Time | C2: Sa | D2: Sv | F2: Time | G2: Sa | H2: Sv | L2: 구분 | M2: αA (단주기스펙트럼 | N2: 전이주기(sec)
B3: 0 | C3: =IF(B3=0,M7,IF(AND(B3>0,B3<=$M$9),$M$7+(($M$8-$M$7)/($M$9-$B$3)*(B3-$B$3)),IF(AND(B3>$M$9,B3<=$M$10),$M$8,IF(AND(B3>$M$10,B3<=$M$11),$M$12/B3,IF(B3>$M$11,$M$13/B3^2))))) -> 0.063 | D3: =(B3/(2*PI()))*(C3*9.81)*$M$15 -> 0 | F3: 0 | G3: =IF(F3=0,P7,IF(AND(F3>0,F3<=$P$9),$P$7+(($P$8-$P$7)/($P$9-$F$3)*(F3-$F$3)),IF(AND(F3>$P$9,F3<=$P$10),$P$8,IF(AND(F3>$P$10,F3<=$P$11),$P$12/F3,IF(F3>$P$11,$P$13/F3^2))))) -> 0.154 | H3: =(F3/(2*PI()))*(G3*9.81)*$P$15 -> 0 | M3: 증폭계수) | N3: T0 | O3: Ts | P3: TL
B4: =B3+0.02 -> 0.02 | C4: =IF(B4=0,M8,IF(AND(B4>0,B4<=$M$9),$M$7+(($M$8-$M$7)/($M$9-$B$3)*(B4-$B$3)),IF(AND(B4>$M$9,B4<=$M$10),$M$8,IF(AND(B4>$M$10,B4<=$M$11),$M$12/B4,IF(B4>$M$11,$M$13/B4^2))))) -> 0.1008 | D4: =(B4/(2*PI()))*(C4*9.81)*$M$15 -> 0.0023858815 | F4: =F3+0.02 -> 0.02 | G4: =IF(F4=0,P8,IF(AND(F4>0,F4<=$P$9),$P$7+(($P$8-$P$7)/($P$9-$F$3)*(F4-$F$3)),IF(AND(F4>$P$9,F4<=$P$10),$P$8,IF(AND(F4>$P$10,F4<=$P$11),$P$12/F4,IF(F4>$P$11,$P$13/F4^2))))) -> 0.2464 | H4: =(F4/(2*PI()))*(G4*9.81)*$P$15 -> 0.0043164101 | L4: 수 평 | M4: 2.8 | N4: 0.06 | O4: 0.3 | P4: 3
B5: =B4+0.02 -> 0.04 | C5: =IF(B5=0,M9,IF(AND(B5>0,B5<=$M$9),$M$7+(($M$8-$M$7)/($M$9-$B$3)*(B5-$B$3)),IF(AND(B5>$M$9,B5<=$M$10),$M$8,IF(AND(B5>$M$10,B5<=$M$11),$M$12/B5,IF(B5>$M$11,$M$13/B5^2))))) -> 0.1386 | D5: =(B5/(2*PI()))*(C5*9.81)*$M$15 -> 0.0065611742 | F5: =F4+0.02 -> 0.04 | G5: =IF(F5=0,P9,IF(AND(F5>0,F5<=$P$9),$P$7+(($P$8-$P$7)/($P$9-$F$3)*(F5-$F$3)),IF(AND(F5>$P$9,F5<=$P$10),$P$8,IF(AND(F5>$P$10,F5<=$P$11),$P$12/F5,IF(F5>$P$11,$P$13/F5^2))))) -> 0.3388 | H5: =(F5/(2*PI()))*(G5*9.81)*$P$15 -> 0.011870128
B6: =B5+0.02 -> 0.06 | C6: =IF(B6=0,M10,IF(AND(B6>0,B6<=$M$9),$M$7+(($M$8-$M$7)/($M$9-$B$3)*(B6-$B$3)),IF(AND(B6>$M$9,B6<=$M$10),$M$8,IF(AND(B6>$M$10,B6<=$M$11),$M$12/B6,IF(B6>$M$11,$M$13/B6^2))))) -> 0.1764 | D6: =(B6/(2*PI()))*(C6*9.81)*$M$15 -> 0.012525878 | F6: =F5+0.02 -> 0.06 | G6: =IF(F6=0,P10,IF(AND(F6>0,F6<=$P$9),$P$7+(($P$8-$P$7)/($P$9-$F$3)*(F6-$F$3)),IF(AND(F6>$P$9,F6<=$P$10),$P$8,IF(AND(F6>$P$10,F6<=$P$11),$P$12/F6,IF(F6>$P$11,$P$13/F6^2))))) -> 0.4312 | H6: =(F6/(2*PI()))*(G6*9.81)*$P$15 -> 0.022661153 | L6: 기능수행수준 | O6: 붕괴방지수준
B7: =B6+0.02 -> 0.08 | C7: =IF(B7=0,M11,IF(AND(B7>0,B7<=$M$9),$M$7+(($M$8-$M$7)/($M$9-$B$3)*(B7-$B$3)),IF(AND(B7>$M$9,B7<=$M$10),$M$8,IF(AND(B7>$M$10,B7<=$M$11),$M$12/B7,IF(B7>$M$11,$M$13/B7^2))))) -> 0.1764 | D7: =(B7/(2*PI()))*(C7*9.81)*$M$15 -> 0.016701171 | F7: =F6+0.02 -> 0.08 | G7: =IF(F7=0,P11,IF(AND(F7>0,F7<=$P$9),$P$7+(($P$8-$P$7)/($P$9-$F$3)*(F7-$F$3)),IF(AND(F7>$P$9,F7<=$P$10),$P$8,IF(AND(F7>$P$10,F7<=$P$11),$P$12/F7,IF(F7>$P$11,$P$13/F7^2))))) -> 0.4312 | H7: =(F7/(2*PI()))*(G7*9.81)*$P$15 -> 0.030214871 | L7: S | M7: 0.063 | O7: S | P7: 0.154
B8: =B7+0.02 -> 0.1 | C8: =IF(B8=0,M12,IF(AND(B8>0,B8<=$M$9),$M$7+(($M$8-$M$7)/($M$9-$B$3)*(B8-$B$3)),IF(AND(B8>$M$9,B8<=$M$10),$M$8,IF(AND(B8>$M$10,B8<=$M$11),$M$12/B8,IF(B8>$M$11,$M$13/B8^2))))) -> 0.1764 | D8: =(B8/(2*PI()))*(C8*9.81)*$M$15 -> 0.020876463 | F8: =F7+0.02 -> 0.1 | G8: =IF(F8=0,P12,IF(AND(F8>0,F8<=$P$9),$P$7+(($P$8-$P$7)/($P$9-$F$3)*(F8-$F$3)),IF(AND(F8>$P$9,F8<=$P$10),$P$8,IF(AND(F8>$P$10,F8<=$P$11),$P$12/F8,IF(F8>$P$11,$P$13/F8^2))))) -> 0.4312 | H8: =(F8/(2*PI()))*(G8*9.81)*$P$15 -> 0.037768588 | L8: αAS | M8: =M7*M4 -> 0.1764 | O8: αAS | P8: =P7*M4 -> 0.4312
B9: =B8+0.02 -> 0.12 | C9: =IF(B9=0,M13,IF(AND(B9>0,B9<=$M$9),$M$7+(($M$8-$M$7)/($M$9-$B$3)*(B9-$B$3)),IF(AND(B9>$M$9,B9<=$M$10),$M$8,IF(AND(B9>$M$10,B9<=$M$11),$M$12/B9,IF(B9>$M$11,$M$13/B9^2))))) -> 0.1764 | D9: =(B9/(2*PI()))*(C9*9.81)*$M$15 -> 0.025051756 | F9: =F8+0.02 -> 0.12 | G9: =IF(F9=0,P13,IF(AND(F9>0,F9<=$P$9),$P$7+(($P$8-$P$7)/($P$9-$F$3)*(F9-$F$3)),IF(AND(F9>$P$9,F9<=$P$10),$P$8,IF(AND(F9>$P$10,F9<=$P$11),$P$12/F9,IF(F9>$P$11,$P$13/F9^2))))) -> 0.4312 | H9: =(F9/(2*PI()))*(G9*9.81)*$P$15 -> 0.045322306 | L9: T0 | M9: 0.06 | O9: T0 | P9: 0.06
B10: =B9+0.02 -> 0.14 | C10: =IF(B10=0,M14,IF(AND(B10>0,B10<=$M$9),$M$7+(($M$8-$M$7)/($M$9-$B$3)*(B10-$B$3)),IF(AND(B10>$M$9,B10<=$M$10),$M$8,IF(AND(B10>$M$10,B10<=$M$11),$M$12/B10,IF(B10>$M$11,$M$13/B10^2))))) -> 0.1764 | D10: =(B10/(2*PI()))*(C10*9.81)*$M$15 -> 0.029227049 | F10: =F9+0.02 -> 0.14 | G10: =IF(F10=0,T25,IF(AND(F10>0,F10<=$P$9),$P$7+(($P$8-$P$7)/($P$9-$F$3)*(F10-$F$3)),IF(AND(F10>$P$9,F10<=$P$10),$P$8,IF(AND(F10>$P$10,F10<=$P$11),$P$12/F10,IF(F10>$P$11,$P$13/F10^2))))) -> 0.4312 | H10: =(F10/(2*PI()))*(G10*9.81)*$P$15 -> 0.052876024 | L10: Ts | M10: 0.3 | O10: Ts | P10: 0.3
B11: =B10+0.02 -> 0.16 | C11: =IF(B11=0,M15,IF(AND(B11>0,B11<=$M$9),$M$7+(($M$8-$M$7)/($M$9-$B$3)*(B11-$B$3)),IF(AND(B11>$M$9,B11<=$M$10),$M$8,IF(AND(B11>$M$10,B11<=$M$11),$M$12/B11,IF(B11>$M$11,$M$13/B11^2))))) -> 0.1764 | D11: =(B11/(2*PI()))*(C11*9.81)*$M$15 -> 0.033402341 | F11: =F10+0.02 -> 0.16 | G11: =IF(F11=0,T26,IF(AND(F11>0,F11<=$P$9),$P$7+(($P$8-$P$7)/($P$9-$F$3)*(F11-$F$3)),IF(AND(F11>$P$9,F11<=$P$10),$P$8,IF(AND(F11>$P$10,F11<=$P$11),$P$12/F11,IF(F11>$P$11,$P$13/F11^2))))) -> 0.4312 | H11: =(F11/(2*PI()))*(G11*9.81)*$P$15 -> 0.060429741 | L11: TL | M11: 3 | O11: TL | P11: 3
B12: =B11+0.02 -> 0.18 | C12: =IF(B12=0,M16,IF(AND(B12>0,B12<=$M$9),$M$7+(($M$8-$M$7)/($M$9-$B$3)*(B12-$B$3)),IF(AND(B12>$M$9,B12<=$M$10),$M$8,IF(AND(B12>$M$10,B12<=$M$11),$M$12/B12,IF(B12>$M$11,$M$13/B12^2))))) -> 0.1764 | D12: =(B12/(2*PI()))*(C12*9.81)*$M$15 -> 0.037577634 | F12: =F11+0.02 -> 0.18 | G12: =IF(F12=0,T27,IF(AND(F12>0,F12<=$P$9),$P$7+(($P$8-$P$7)/($P$9-$F$3)*(F12-$F$3)),IF(AND(F12>$P$9,F12<=$P$10),$P$8,IF(AND(F12>$P$10,F12<=$P$11),$P$12/F12,IF(F12>$P$11,$P$13/F12^2))))) -> 0.4312 | H12: =(F12/(2*PI()))*(G12*9.81)*$P$15 -> 0.067983459 | L12: Ts*αAS | M12: =M10*M8 -> 0.05292 | O12: Ts*αAS | P12: =P10*P8 -> 0.12936
B13: =B12+0.02 -> 0.2 | C13: =IF(B13=0,M17,IF(AND(B13>0,B13<=$M$9),$M$7+(($M$8-$M$7)/($M$9-$B$3)*(B13-$B$3)),IF(AND(B13>$M$9,B13<=$M$10),$M$8,IF(AND(B13>$M$10,B13<=$M$11),$M$12/B13,IF(B13>$M$11,$M$13/B13^2))))) -> 0.1764 | D13: =(B13/(2*PI()))*(C13*9.81)*$M$15 -> 0.041752927 | F13: =F12+0.02 -> 0.2 | G13: =IF(F13=0,T28,IF(AND(F13>0,F13<=$P$9),$P$7+(($P$8-$P$7)/($P$9-$F$3)*(F13-$F$3)),IF(AND(F13>$P$9,F13<=$P$10),$P$8,IF(AND(F13>$P$10,F13<=$P$11),$P$12/F13,IF(F13>$P$11,$P$13/F13^2))))) -> 0.4312 | H13: =(F13/(2*PI()))*(G13*9.81)*$P$15 -> 0.075537177 | L13: TL*αAS | M13: =M10*M8*M11 -> 0.15876 | O13: TL*αAS | P13: =P10*P8*P11 -> 0.38808
B14: =B13+0.02 -> 0.22 | C14: =IF(B14=0,M18,IF(AND(B14>0,B14<=$M$9),$M$7+(($M$8-$M$7)/($M$9-$B$3)*(B14-$B$3)),IF(AND(B14>$M$9,B14<=$M$10),$M$8,IF(AND(B14>$M$10,B14<=$M$11),$M$12/B14,IF(B14>$M$11,$M$13/B14^2))))) -> 0.1764 | D14: =(B14/(2*PI()))*(C14*9.81)*$M$15 -> 0.045928219 | F14: =F13+0.02 -> 0.22 | G14: =IF(F14=0,T29,IF(AND(F14>0,F14<=$P$9),$P$7+(($P$8-$P$7)/($P$9-$F$3)*(F14-$F$3)),IF(AND(F14>$P$9,F14<=$P$10),$P$8,IF(AND(F14>$P$10,F14<=$P$11),$P$12/F14,IF(F14>$P$11,$P$13/F14^2))))) -> 0.4312 | H14: =(F14/(2*PI()))*(G14*9.81)*$P$15 -> 0.083090894
B15: =B14+0.02 -> 0.24 | C15: =IF(B15=0,M19,IF(AND(B15>0,B15<=$M$9),$M$7+(($M$8-$M$7)/($M$9-$B$3)*(B15-$B$3)),IF(AND(B15>$M$9,B15<=$M$10),$M$8,IF(AND(B15>$M$10,B15<=$M$11),$M$12/B15,IF(B15>$M$11,$M$13/B15^2))))) -> 0.1764 | D15: =(B15/(2*PI()))*(C15*9.81)*$M$15 -> 0.050103512 | F15: =F14+0.02 -> 0.24 | G15: =IF(F15=0,T30,IF(AND(F15>0,F15<=$P$9),$P$7+(($P$8-$P$7)/($P$9-$F$3)*(F15-$F$3)),IF(AND(F15>$P$9,F15<=$P$10),$P$8,IF(AND(F15>$P$10,F15<=$P$11),$P$12/F15,IF(F15>$P$11,$P$13/F15^2))))) -> 0.4312 | H15: =(F15/(2*PI()))*(G15*9.81)*$P$15 -> 0.090644612 | L15: CD | M15: 0.758 | O15: CD | P15: 0.561
B16: =B15+0.02 -> 0.26 | C16: =IF(B16=0,M20,IF(AND(B16>0,B16<=$M$9),$M$7+(($M$8-$M$7)/($M$9-$B$3)*(B16-$B$3)),IF(AND(B16>$M$9,B16<=$M$10),$M$8,IF(AND(B16>$M$10,B16<=$M$11),$M$12/B16,IF(B16>$M$11,$M$13/B16^2))))) -> 0.1764 | D16: =(B16/(2*PI()))*(C16*9.81)*$M$15 -> 0.054278804 | F16: =F15+0.02 -> 0.26 | G16: =IF(F16=0,T31,IF(AND(F16>0,F16<=$P$9),$P$7+(($P$8-$P$7)/($P$9-$F$3)*(F16-$F$3)),IF(AND(F16>$P$9,F16<=$P$10),$P$8,IF(AND(F16>$P$10,F16<=$P$11),$P$12/F16,IF(F16>$P$11,$P$13/F16^2))))) -> 0.4312 | H16: =(F16/(2*PI()))*(G16*9.81)*$P$15 -> 0.09819833
B17: =B16+0.02 -> 0.28 | C17: =IF(B17=0,M21,IF(AND(B17>0,B17<=$M$9),$M$7+(($M$8-$M$7)/($M$9-$B$3)*(B17-$B$3)),IF(AND(B17>$M$9,B17<=$M$10),$M$8,IF(AND(B17>$M$10,B17<=$M$11),$M$12/B17,IF(B17>$M$11,$M$13/B17^2))))) -> 0.1764 | D17: =(B17/(2*PI()))*(C17*9.81)*$M$15 -> 0.058454097 | F17: =F16+0.02 -> 0.28 | G17: =IF(F17=0,T32,IF(AND(F17>0,F17<=$P$9),$P$7+(($P$8-$P$7)/($P$9-$F$3)*(F17-$F$3)),IF(AND(F17>$P$9,F17<=$P$10),$P$8,IF(AND(F17>$P$10,F17<=$P$11),$P$12/F17,IF(F17>$P$11,$P$13/F17^2))))) -> 0.4312 | H17: =(F17/(2*PI()))*(G17*9.81)*$P$15 -> 0.10575205
B18: =B17+0.02 -> 0.3 | C18: =IF(B18=0,M22,IF(AND(B18>0,B18<=$M$9),$M$7+(($M$8-$M$7)/($M$9-$B$3)*(B18-$B$3)),IF(AND(B18>$M$9,B18<=$M$10),$M$8,IF(AND(B18>$M$10,B18<=$M$11),$M$12/B18,IF(B18>$M$11,$M$13/B18^2))))) -> 0.1764 | D18: =(B18/(2*PI()))*(C18*9.81)*$M$15 -> 0.06262939 | F18: =F17+0.02 -> 0.3 | G18: =IF(F18=0,T33,IF(AND(F18>0,F18<=$P$9),$P$7+(($P$8-$P$7)/($P$9-$F$3)*(F18-$F$3)),IF(AND(F18>$P$9,F18<=$P$10),$P$8,IF(AND(F18>$P$10,F18<=$P$11),$P$12/F18,IF(F18>$P$11,$P$13/F18^2))))) -> 0.4312 | H18: =(F18/(2*PI()))*(G18*9.81)*$P$15 -> 0.11330576
B19: =B18+0.02 -> 0.32 | C19: =IF(B19=0,M23,IF(AND(B19>0,B19<=$M$9),$M$7+(($M$8-$M$7)/($M$9-$B$3)*(B19-$B$3)),IF(AND(B19>$M$9,B19<=$M$10),$M$8,IF(AND(B19>$M$10,B19<=$M$11),$M$12/B19,IF(B19>$M$11,$M$13/B19^2))))) -> 0.165375 | D19: =(B19/(2*PI()))*(C19*9.81)*$M$15 -> 0.06262939 | F19: =F18+0.02 -> 0.32 | G19: =IF(F19=0,T34,IF(AND(F19>0,F19<=$P$9),$P$7+(($P$8-$P$7)/($P$9-$F$3)*(F19-$F$3)),IF(AND(F19>$P$9,F19<=$P$10),$P$8,IF(AND(F19>$P$10,F19<=$P$11),$P$12/F19,IF(F19>$P$11,$P$13/F19^2))))) -> 0.40425 | H19: =(F19/(2*PI()))*(G19*9.81)*$P$15 -> 0.11330576
B20: =B19+0.02 -> 0.34 | C20: =IF(B20=0,M24,IF(AND(B20>0,B20<=$M$9),$M$7+(($M$8-$M$7)/($M$9-$B$3)*(B20-$B$3)),IF(AND(B20>$M$9,B20<=$M$10),$M$8,IF(AND(B20>$M$10,B20<=$M$11),$M$12/B20,IF(B20>$M$11,$M$13/B20^2))))) -> 0.15564706 | D20: =(B20/(2*PI()))*(C20*9.81)*$M$15 -> 0.06262939 | F20: =F19+0.02 -> 0.34 | G20: =IF(F20=0,T35,IF(AND(F20>0,F20<=$P$9),$P$7+(($P$8-$P$7)/($P$9-$F$3)*(F20-$F$3)),IF(AND(F20>$P$9,F20<=$P$10),$P$8,IF(AND(F20>$P$10,F20<=$P$11),$P$12/F20,IF(F20>$P$11,$P$13/F20^2))))) -> 0.38047059 | H20: =(F20/(2*PI()))*(G20*9.81)*$P$15 -> 0.11330576
B21: =B20+0.02 -> 0.36 | C21: =IF(B21=0,M25,IF(AND(B21>0,B21<=$M$9),$M$7+(($M$8-$M$7)/($M$9-$B$3)*(B21-$B$3)),IF(AND(B21>$M$9,B21<=$M$10),$M$8,IF(AND(B21>$M$10,B21<=$M$11),$M$12/B21,IF(B21>$M$11,$M$13/B21^2))))) -> 0.147 | D21: =(B21/(2*PI()))*(C21*9.81)*$M$15 -> 0.06262939 | F21: =F20+0.02 -> 0.36 | G21: =IF(F21=0,T36,IF(AND(F21>0,F21<=$P$9),$P$7+(($P$8-$P$7)/($P$9-$F$3)*(F21-$F$3)),IF(AND(F21>$P$9,F21<=$P$10),$P$8,IF(AND(F21>$P$10,F21<=$P$11),$P$12/F21,IF(F21>$P$11,$P$13/F21^2))))) -> 0.35933333 | H21: =(F21/(2*PI()))*(G21*9.81)*$P$15 -> 0.11330576
B22: =B21+0.02 -> 0.38 | C22: =IF(B22=0,M26,IF(AND(B22>0,B22<=$M$9),$M$7+(($M$8-$M$7)/($M$9-$B$3)*(B22-$B$3)),IF(AND(B22>$M$9,B22<=$M$10),$M$8,IF(AND(B22>$M$10,B22<=$M$11),$M$12/B22,IF(B22>$M$11,$M$13/B22^2))))) -> 0.13926316 | D22: =(B22/(2*PI()))*(C22*9.81)*$M$15 -> 0.06262939 | F22: =F21+0.02 -> 0.38 | G22: =IF(F22=0,T37,IF(AND(F22>0,F22<=$P$9),$P$7+(($P$8-$P$7)/($P$9-$F$3)*(F22-$F$3)),IF(AND(F22>$P$9,F22<=$P$10),$P$8,IF(AND(F22>$P$10,F22<=$P$11),$P$12/F22,IF(F22>$P$11,$P$13/F22^2))))) -> 0.34042105 | H22: =(F22/(2*PI()))*(G22*9.81)*$P$15 -> 0.11330576
B23: =B22+0.02 -> 0.4 | C23: =IF(B23=0,M27,IF(AND(B23>0,B23<=$M$9),$M$7+(($M$8-$M$7)/($M$9-$B$3)*(B23-$B$3)),IF(AND(B23>$M$9,B23<=$M$10),$M$8,IF(AND(B23>$M$10,B23<=$M$11),$M$12/B23,IF(B23>$M$11,$M$13/B23^2))))) -> 0.1323 | D23: =(B23/(2*PI()))*(C23*9.81)*$M$15 -> 0.06262939 | F23: =F22+0.02 -> 0.4 | G23: =IF(F23=0,T38,IF(AND(F23>0,F23<=$P$9),$P$7+(($P$8-$P$7)/($P$9-$F$3)*(F23-$F$3)),IF(AND(F23>$P$9,F23<=$P$10),$P$8,IF(AND(F23>$P$10,F23<=$P$11),$P$12/F23,IF(F23>$P$11,$P$13/F23^2))))) -> 0.3234 | H23: =(F23/(2*PI()))*(G23*9.81)*$P$15 -> 0.11330576
B24: =B23+0.02 -> 0.42 | C24: =IF(B24=0,M28,IF(AND(B24>0,B24<=$M$9),$M$7+(($M$8-$M$7)/($M$9-$B$3)*(B24-$B$3)),IF(AND(B24>$M$9,B24<=$M$10),$M$8,IF(AND(B24>$M$10,B24<=$M$11),$M$12/B24,IF(B24>$M$11,$M$13/B24^2))))) -> 0.126 | D24: =(B24/(2*PI()))*(C24*9.81)*$M$15 -> 0.06262939 | F24: =F23+0.02 -> 0.42 | G24: =IF(F24=0,T39,IF(AND(F24>0,F24<=$P$9),$P$7+(($P$8-$P$7)/($P$9-$F$3)*(F24-$F$3)),IF(AND(F24>$P$9,F24<=$P$10),$P$8,IF(AND(F24>$P$10,F24<=$P$11),$P$12/F24,IF(F24>$P$11,$P$13/F24^2))))) -> 0.308 | H24: =(F24/(2*PI()))*(G24*9.81)*$P$15 -> 0.11330576
B25: =B24+0.02 -> 0.44 | C25: =IF(B25=0,M29,IF(AND(B25>0,B25<=$M$9),$M$7+(($M$8-$M$7)/($M$9-$B$3)*(B25-$B$3)),IF(AND(B25>$M$9,B25<=$M$10),$M$8,IF(AND(B25>$M$10,B25<=$M$11),$M$12/B25,IF(B25>$M$11,$M$13/B25^2))))) -> 0.12027273 | D25: =(B25/(2*PI()))*(C25*9.81)*$M$15 -> 0.06262939 | F25: =F24+0.02 -> 0.44 | G25: =IF(F25=0,T40,IF(AND(F25>0,F25<=$P$9),$P$7+(($P$8-$P$7)/($P$9-$F$3)*(F25-$F$3)),IF(AND(F25>$P$9,F25<=$P$10),$P$8,IF(AND(F25>$P$10,F25<=$P$11),$P$12/F25,IF(F25>$P$11,$P$13/F25^2))))) -> 0.294 | H25: =(F25/(2*PI()))*(G25*9.81)*$P$15 -> 0.11330576
B26: =B25+0.02 -> 0.46 | C26: =IF(B26=0,M30,IF(AND(B26>0,B26<=$M$9),$M$7+(($M$8-$M$7)/($M$9-$B$3)*(B26-$B$3)),IF(AND(B26>$M$9,B26<=$M$10),$M$8,IF(AND(B26>$M$10,B26<=$M$11),$M$12/B26,IF(B26>$M$11,$M$13/B26^2))))) -> 0.11504348 | D26: =(B26/(2*PI()))*(C26*9.81)*$M$15 -> 0.06262939 | F26: =F25+0.02 -> 0.46 | G26: =IF(F26=0,T41,IF(AND(F26>0,F26<=$P$9),$P$7+(($P$8-$P$7)/($P$9-$F$3)*(F26-$F$3)),IF(AND(F26>$P$9,F26<=$P$10),$P$8,IF(AND(F26>$P$10,F26<=$P$11),$P$12/F26,IF(F26>$P$11,$P$13/F26^2))))) -> 0.28121739 | H26: =(F26/(2*PI()))*(G26*9.81)*$P$15 -> 0.11330576
B27: =B26+0.02 -> 0.48 | C27: =IF(B27=0,M31,IF(AND(B27>0,B27<=$M$9),$M$7+(($M$8-$M$7)/($M$9-$B$3)*(B27-$B$3)),IF(AND(B27>$M$9,B27<=$M$10),$M$8,IF(AND(B27>$M$10,B27<=$M$11),$M$12/B27,IF(B27>$M$11,$M$13/B27^2))))) -> 0.11025 | D27: =(B27/(2*PI()))*(C27*9.81)*$M$15 -> 0.06262939 | F27: =F26+0.02 -> 0.48 | G27: =IF(F27=0,T42,IF(AND(F27>0,F27<=$P$9),$P$7+(($P$8-$P$7)/($P$9-$F$3)*(F27-$F$3)),IF(AND(F27>$P$9,F27<=$P$10),$P$8,IF(AND(F27>$P$10,F27<=$P$11),$P$12/F27,IF(F27>$P$11,$P$13/F27^2))))) -> 0.2695 | H27: =(F27/(2*PI()))*(G27*9.81)*$P$15 -> 0.11330576
... B58: =B57+0.02 -> 1.1 | C58: =IF(B58=0,M62,IF(AND(B58>0,B58<=$M$9),$M$7+(($M$8-$M$7)/($M$9-$B$3)*(B58-$B$3)),IF(AND(B58>$M$9,B58<=$M$10),$M$8,IF(AND(B58>$M$10,B58<=$M$11),$M$12/B58,IF(B58>$M$11,$M$13/B58^2))))) -> 0.048109091 | D58: =(B58/(2*PI()))*(C58*9.81)*$M$15 -> 0.06262939 | F58: =F57+0.02 -> 1.1 | G58: =IF(F58=0,T73,IF(AND(F58>0,F58<=$P$9),$P$7+(($P$8-$P$7)/($P$9-$F$3)*(F58-$F$3)),IF(AND(F58>$P$9,F58<=$P$10),$P$8,IF(AND(F58>$P$10,F58<=$P$11),$P$12/F58,IF(F58>$P$11,$P$13/F58^2))))) -> 0.1176 | H58: =(F58/(2*PI()))*(G58*9.81)*$P$15 -> 0.11330576
B59: =B58+0.02 -> 1.12 | C59: =IF(B59=0,M63,IF(AND(B59>0,B59<=$M$9),$M$7+(($M$8-$M$7)/($M$9-$B$3)*(B59-$B$3)),IF(AND(B59>$M$9,B59<=$M$10),$M$8,IF(AND(B59>$M$10,B59<=$M$11),$M$12/B59,IF(B59>$M$11,$M$13/B59^2))))) -> 0.04725 | D59: =(B59/(2*PI()))*(C59*9.81)*$M$15 -> 0.06262939 | F59: =F58+0.02 -> 1.12 | G59: =IF(F59=0,T74,IF(AND(F59>0,F59<=$P$9),$P$7+(($P$8-$P$7)/($P$9-$F$3)*(F59-$F$3)),IF(AND(F59>$P$9,F59<=$P$10),$P$8,IF(AND(F59>$P$10,F59<=$P$11),$P$12/F59,IF(F59>$P$11,$P$13/F59^2))))) -> 0.1155 | H59: =(F59/(2*PI()))*(G59*9.81)*$P$15 -> 0.11330576 | K59: 만든사람 : 송광석
B60: =B59+0.02 -> 1.14 | C60: =IF(B60=0,M64,IF(AND(B60>0,B60<=$M$9),$M$7+(($M$8-$M$7)/($M$9-$B$3)*(B60-$B$3)),IF(AND(B60>$M$9,B60<=$M$10),$M$8,IF(AND(B60>$M$10,B60<=$M$11),$M$12/B60,IF(B60>$M$11,$M$13/B60^2))))) -> 0.046421053 | D60: =(B60/(2*PI()))*(C60*9.81)*$M$15 -> 0.06262939 | F60: =F59+0.02 -> 1.14 | G60: =IF(F60=0,T75,IF(AND(F60>0,F60<=$P$9),$P$7+(($P$8-$P$7)/($P$9-$F$3)*(F60-$F$3)),IF(AND(F60>$P$9,F60<=$P$10),$P$8,IF(AND(F60>$P$10,F60<=$P$11),$P$12/F60,IF(F60>$P$11,$P$13/F60^2))))) -> 0.11347368 | H60: =(F60/(2*PI()))*(G60*9.81)*$P$15 -> 0.11330576 | K60: 만든날짜 : 2021-12-14
B61: =B60+0.02 -> 1.16 | C61: =IF(B61=0,M65,IF(AND(B61>0,B61<=$M$9),$M$7+(($M$8-$M$7)/($M$9-$B$3)*(B61-$B$3)),IF(AND(B61>$M$9,B61<=$M$10),$M$8,IF(AND(B61>$M$10,B61<=$M$11),$M$12/B61,IF(B61>$M$11,$M$13/B61^2))))) -> 0.04562069 | D61: =(B61/(2*PI()))*(C61*9.81)*$M$15 -> 0.06262939 | F61: =F60+0.02 -> 1.16 | G61: =IF(F61=0,T76,IF(AND(F61>0,F61<=$P$9),$P$7+(($P$8-$P$7)/($P$9-$F$3)*(F61-$F$3)),IF(AND(F61>$P$9,F61<=$P$10),$P$8,IF(AND(F61>$P$10,F61<=$P$11),$P$12/F61,IF(F61>$P$11,$P$13/F61^2))))) -> 0.11151724 | H61: =(F61/(2*PI()))*(G61*9.81)*$P$15 -> 0.11330576 | K61: 현재 Version : 1.02
B62: =B61+0.02 -> 1.18 | C62: =IF(B62=0,M66,IF(AND(B62>0,B62<=$M$9),$M$7+(($M$8-$M$7)/($M$9-$B$3)*(B62-$B$3)),IF(AND(B62>$M$9,B62<=$M$10),$M$8,IF(AND(B62>$M$10,B62<=$M$11),$M$12/B62,IF(B62>$M$11,$M$13/B62^2))))) -> 0.044847458 | D62: =(B62/(2*PI()))*(C62*9.81)*$M$15 -> 0.06262939 | F62: =F61+0.02 -> 1.18 | G62: =IF(F62=0,T77,IF(AND(F62>0,F62<=$P$9),$P$7+(($P$8-$P$7)/($P$9-$F$3)*(F62-$F$3)),IF(AND(F62>$P$9,F62<=$P$10),$P$8,IF(AND(F62>$P$10,F62<=$P$11),$P$12/F62,IF(F62>$P$11,$P$13/F62^2))))) -> 0.10962712 | H62: =(F62/(2*PI()))*(G62*9.81)*$P$15 -> 0.11330576 | K62: version
B63: =B62+0.02 -> 1.2 | C63: =IF(B63=0,M67,IF(AND(B63>0,B63<=$M$9),$M$7+(($M$8-$M$7)/($M$9-$B$3)*(B63-$B$3)),IF(AND(B63>$M$9,B63<=$M$10),$M$8,IF(AND(B63>$M$10,B63<=$M$11),$M$12/B63,IF(B63>$M$11,$M$13/B63^2))))) -> 0.0441 | D63: =(B63/(2*PI()))*(C63*9.81)*$M$15 -> 0.06262939 | F63: =F62+0.02 -> 1.2 | G63: =IF(F63=0,T78,IF(AND(F63>0,F63<=$P$9),$P$7+(($P$8-$P$7)/($P$9-$F$3)*(F63-$F$3)),IF(AND(F63>$P$9,F63<=$P$10),$P$8,IF(AND(F63>$P$10,F63<=$P$11),$P$12/F63,IF(F63>$P$11,$P$13/F63^2))))) -> 0.1078 | H63: =(F63/(2*PI()))*(G63*9.81)*$P$15 -> 0.11330576 | K63: Version : 1.00
B64: =B63+0.02 -> 1.22 | C64: =IF(B64=0,M68,IF(AND(B64>0,B64<=$M$9),$M$7+(($M$8-$M$7)/($M$9-$B$3)*(B64-$B$3)),IF(AND(B64>$M$9,B64<=$M$10),$M$8,IF(AND(B64>$M$10,B64<=$M$11),$M$12/B64,IF(B64>$M$11,$M$13/B64^2))))) -> 0.043377049 | D64: =(B64/(2*PI()))*(C64*9.81)*$M$15 -> 0.06262939 | F64: =F63+0.02 -> 1.22 | G64: =IF(F64=0,T79,IF(AND(F64>0,F64<=$P$9),$P$7+(($P$8-$P$7)/($P$9-$F$3)*(F64-$F$3)),IF(AND(F64>$P$9,F64<=$P$10),$P$8,IF(AND(F64>$P$10,F64<=$P$11),$P$12/F64,IF(F64>$P$11,$P$13/F64^2))))) -> 0.10603279 | H64: =(F64/(2*PI()))*(G64*9.81)*$P$15 -> 0.11330576 | K64: - 개정 「기존 시설물(상수도) 내진성능 평가요령(2021.09)」 적용
B65: =B64+0.02 -> 1.24 | C65: =IF(B65=0,M69,IF(AND(B65>0,B65<=$M$9),$M$7+(($M$8-$M$7)/($M$9-$B$3)*(B65-$B$3)),IF(AND(B65>$M$9,B65<=$M$10),$M$8,IF(AND(B65>$M$10,B65<=$M$11),$M$12/B65,IF(B65>$M$11,$M$13/B65^2))))) -> 0.042677419 | D65: =(B65/(2*PI()))*(C65*9.81)*$M$15 -> 0.06262939 | F65: =F64+0.02 -> 1.24 | G65: =IF(F65=0,T80,IF(AND(F65>0,F65<=$P$9),$P$7+(($P$8-$P$7)/($P$9-$F$3)*(F65-$F$3)),IF(AND(F65>$P$9,F65<=$P$10),$P$8,IF(AND(F65>$P$10,F65<=$P$11),$P$12/F65,IF(F65>$P$11,$P$13/F65^2))))) -> 0.10432258 | H65: =(F65/(2*PI()))*(G65*9.81)*$P$15 -> 0.11330576 | K65: Version : 1.01
B66: =B65+0.02 -> 1.26 | C66: =IF(B66=0,M70,IF(AND(B66>0,B66<=$M$9),$M$7+(($M$8-$M$7)/($M$9-$B$3)*(B66-$B$3)),IF(AND(B66>$M$9,B66<=$M$10),$M$8,IF(AND(B66>$M$10,B66<=$M$11),$M$12/B66,IF(B66>$M$11,$M$13/B66^2))))) -> 0.042 | D66: =(B66/(2*PI()))*(C66*9.81)*$M$15 -> 0.06262939 | F66: =F65+0.02 -> 1.26 | G66: =IF(F66=0,T81,IF(AND(F66>0,F66<=$P$9),$P$7+(($P$8-$P$7)/($P$9-$F$3)*(F66-$F$3)),IF(AND(F66>$P$9,F66<=$P$10),$P$8,IF(AND(F66>$P$10,F66<=$P$11),$P$12/F66,IF(F66>$P$11,$P$13/F66^2))))) -> 0.10266667 | H66: =(F66/(2*PI()))*(G66*9.81)*$P$15 -> 0.11330576 | K66: - 표층지반 평균 전단파속도 산정 정리
B67: =B66+0.02 -> 1.28 | C67: =IF(B67=0,M71,IF(AND(B67>0,B67<=$M$9),$M$7+(($M$8-$M$7)/($M$9-$B$3)*(B67-$B$3)),IF(AND(B67>$M$9,B67<=$M$10),$M$8,IF(AND(B67>$M$10,B67<=$M$11),$M$12/B67,IF(B67>$M$11,$M$13/B67^2))))) -> 0.04134375 | D67: =(B67/(2*PI()))*(C67*9.81)*$M$15 -> 0.06262939 | F67: =F66+0.02 -> 1.28 | G67: =IF(F67=0,T82,IF(AND(F67>0,F67<=$P$9),$P$7+(($P$8-$P$7)/($P$9-$F$3)*(F67-$F$3)),IF(AND(F67>$P$9,F67<=$P$10),$P$8,IF(AND(F67>$P$10,F67<=$P$11),$P$12/F67,IF(F67>$P$11,$P$13/F67^2))))) -> 0.1010625 | H67: =(F67/(2*PI()))*(G67*9.81)*$P$15 -> 0.11330576 | K67: - 내용 일부 수정
B68: =B67+0.02 -> 1.3 | C68: =IF(B68=0,M72,IF(AND(B68>0,B68<=$M$9),$M$7+(($M$8-$M$7)/($M$9-$B$3)*(B68-$B$3)),IF(AND(B68>$M$9,B68<=$M$10),$M$8,IF(AND(B68>$M$10,B68<=$M$11),$M$12/B68,IF(B68>$M$11,$M$13/B68^2))))) -> 0.040707692 | D68: =(B68/(2*PI()))*(C68*9.81)*$M$15 -> 0.06262939 | F68: =F67+0.02 -> 1.3 | G68: =IF(F68=0,T83,IF(AND(F68>0,F68<=$P$9),$P$7+(($P$8-$P$7)/($P$9-$F$3)*(F68-$F$3)),IF(AND(F68>$P$9,F68<=$P$10),$P$8,IF(AND(F68>$P$10,F68<=$P$11),$P$12/F68,IF(F68>$P$11,$P$13/F68^2))))) -> 0.099507692 | H68: =(F68/(2*PI()))*(G68*9.81)*$P$15 -> 0.11330576 | K68: Version : 1.02
B69: =B68+0.02 -> 1.32 | C69: =IF(B69=0,M73,IF(AND(B69>0,B69<=$M$9),$M$7+(($M$8-$M$7)/($M$9-$B$3)*(B69-$B$3)),IF(AND(B69>$M$9,B69<=$M$10),$M$8,IF(AND(B69>$M$10,B69<=$M$11),$M$12/B69,IF(B69>$M$11,$M$13/B69^2))))) -> 0.040090909 | D69: =(B69/(2*PI()))*(C69*9.81)*$M$15 -> 0.06262939 | F69: =F68+0.02 -> 1.32 | G69: =IF(F69=0,T84,IF(AND(F69>0,F69<=$P$9),$P$7+(($P$8-$P$7)/($P$9-$F$3)*(F69-$F$3)),IF(AND(F69>$P$9,F69<=$P$10),$P$8,IF(AND(F69>$P$10,F69<=$P$11),$P$12/F69,IF(F69>$P$11,$P$13/F69^2))))) -> 0.098 | H69: =(F69/(2*PI()))*(G69*9.81)*$P$15 -> 0.11330576 | K69: - 오타 및 표시 자릿수 수정
B70: =B69+0.02 -> 1.34 | C70: =IF(B70=0,M74,IF(AND(B70>0,B70<=$M$9),$M$7+(($M$8-$M$7)/($M$9-$B$3)*(B70-$B$3)),IF(AND(B70>$M$9,B70<=$M$10),$M$8,IF(AND(B70>$M$10,B70<=$M$11),$M$12/B70,IF(B70>$M$11,$M$13/B70^2))))) -> 0.039492537 | D70: =(B70/(2*PI()))*(C70*9.81)*$M$15 -> 0.06262939 | F70: =F69+0.02 -> 1.34 | G70: =IF(F70=0,T85,IF(AND(F70>0,F70<=$P$9),$P$7+(($P$8-$P$7)/($P$9-$F$3)*(F70-$F$3)),IF(AND(F70>$P$9,F70<=$P$10),$P$8,IF(AND(F70>$P$10,F70<=$P$11),$P$12/F70,IF(F70>$P$11,$P$13/F70^2))))) -> 0.096537313 | H70: =(F70/(2*PI()))*(G70*9.81)*$P$15 -> 0.11330576
...
